[2025-03-30T12:31:53.216+0000] {local_task_job_runner.py:123} INFO - ::group::Pre task execution logs
[2025-03-30T12:31:53.237+0000] {taskinstance.py:2613} INFO - Dependencies all met for dep_context=non-requeueable deps ti=<TaskInstance: aqi_etl_pipeline.validate_aqi_data_Ayutthaya manual__2025-03-30T12:20:58.350966+00:00 [queued]>
[2025-03-30T12:31:53.248+0000] {taskinstance.py:2613} INFO - Dependencies all met for dep_context=requeueable deps ti=<TaskInstance: aqi_etl_pipeline.validate_aqi_data_Ayutthaya manual__2025-03-30T12:20:58.350966+00:00 [queued]>
[2025-03-30T12:31:53.249+0000] {taskinstance.py:2866} INFO - Starting attempt 3 of 4
[2025-03-30T12:31:53.267+0000] {taskinstance.py:2889} INFO - Executing <Task(PythonOperator): validate_aqi_data_Ayutthaya> on 2025-03-30 12:20:58.350966+00:00
[2025-03-30T12:31:53.283+0000] {standard_task_runner.py:104} INFO - Running: ['***', 'tasks', 'run', 'aqi_etl_pipeline', 'validate_aqi_data_Ayutthaya', 'manual__2025-03-30T12:20:58.350966+00:00', '--job-id', '613', '--raw', '--subdir', 'DAGS_FOLDER/api_etl_pipeline.py', '--cfg-path', '/tmp/tmpkxy92si6']
[2025-03-30T12:31:53.286+0000] {standard_task_runner.py:105} INFO - Job 613: Subtask validate_aqi_data_Ayutthaya
[2025-03-30T12:31:53.290+0000] {logging_mixin.py:190} WARNING - /home/***/.local/lib/python3.12/site-packages/***/task/task_runner/standard_task_runner.py:70 DeprecationWarning: This process (pid=31794) is multi-threaded, use of fork() may lead to deadlocks in the child.
[2025-03-30T12:31:53.291+0000] {standard_task_runner.py:72} INFO - Started process 31808 to run task
[2025-03-30T12:31:53.345+0000] {task_command.py:467} INFO - Running <TaskInstance: aqi_etl_pipeline.validate_aqi_data_Ayutthaya manual__2025-03-30T12:20:58.350966+00:00 [running]> on host 58b9640d9ecf
[2025-03-30T12:31:53.461+0000] {taskinstance.py:3132} INFO - Exporting env vars: AIRFLOW_CTX_DAG_OWNER='***' AIRFLOW_CTX_DAG_ID='aqi_etl_pipeline' AIRFLOW_CTX_TASK_ID='validate_aqi_data_Ayutthaya' AIRFLOW_CTX_EXECUTION_DATE='2025-03-30T12:20:58.350966+00:00' AIRFLOW_CTX_TRY_NUMBER='3' AIRFLOW_CTX_DAG_RUN_ID='manual__2025-03-30T12:20:58.350966+00:00'
[2025-03-30T12:31:53.462+0000] {logging_mixin.py:190} INFO - Task instance is in running state
[2025-03-30T12:31:53.463+0000] {logging_mixin.py:190} INFO -  Previous state of the Task instance: queued
[2025-03-30T12:31:53.464+0000] {logging_mixin.py:190} INFO - Current task name:validate_aqi_data_Ayutthaya state:running start_date:2025-03-30 12:31:53.237806+00:00
[2025-03-30T12:31:53.464+0000] {logging_mixin.py:190} INFO - Dag name:aqi_etl_pipeline and current dag run status:running
[2025-03-30T12:31:53.465+0000] {taskinstance.py:731} INFO - ::endgroup::
[2025-03-30T12:31:53.466+0000] {logging_mixin.py:190} INFO - ‚ùå File Not Found: /opt/***/dags/aqi_data_Ayutthaya.json
[2025-03-30T12:31:53.467+0000] {taskinstance.py:3311} ERROR - Task failed with exception
Traceback (most recent call last):
  File "/opt/airflow/dags/api_etl_pipeline.py", line 74, in _validate_aqi_data
    with open(f"{DAG_FOLDER}/aqi_data_{city}.json", "r") as f:
         ^^^^^^^^^^^^^^^^^^^^^^^^^^^^^^^^^^^^^^^^^^^^^^^
FileNotFoundError: [Errno 2] No such file or directory: '/opt/airflow/dags/aqi_data_Ayutthaya.json'

During handling of the above exception, another exception occurred:

Traceback (most recent call last):
  File "/home/airflow/.local/lib/python3.12/site-packages/airflow/models/taskinstance.py", line 767, in _execute_task
    result = _execute_callable(context=context, **execute_callable_kwargs)
             ^^^^^^^^^^^^^^^^^^^^^^^^^^^^^^^^^^^^^^^^^^^^^^^^^^^^^^^^^^^^^
  File "/home/airflow/.local/lib/python3.12/site-packages/airflow/models/taskinstance.py", line 733, in _execute_callable
    return ExecutionCallableRunner(
           ^^^^^^^^^^^^^^^^^^^^^^^^
  File "/home/airflow/.local/lib/python3.12/site-packages/airflow/utils/operator_helpers.py", line 252, in run
    return self.func(*args, **kwargs)
           ^^^^^^^^^^^^^^^^^^^^^^^^^^
  File "/home/airflow/.local/lib/python3.12/site-packages/airflow/models/baseoperator.py", line 422, in wrapper
    return func(self, *args, **kwargs)
           ^^^^^^^^^^^^^^^^^^^^^^^^^^^
  File "/home/airflow/.local/lib/python3.12/site-packages/airflow/operators/python.py", line 238, in execute
    return_value = self.execute_callable()
                   ^^^^^^^^^^^^^^^^^^^^^^^
  File "/home/airflow/.local/lib/python3.12/site-packages/airflow/operators/python.py", line 256, in execute_callable
    return runner.run(*self.op_args, **self.op_kwargs)
           ^^^^^^^^^^^^^^^^^^^^^^^^^^^^^^^^^^^^^^^^^^^
  File "/home/airflow/.local/lib/python3.12/site-packages/airflow/utils/operator_helpers.py", line 252, in run
    return self.func(*args, **kwargs)
           ^^^^^^^^^^^^^^^^^^^^^^^^^^
  File "/opt/airflow/dags/api_etl_pipeline.py", line 106, in _validate_aqi_data
    raise ValueError(f"Missing data file for {city}. Please check API request.")
ValueError: Missing data file for Ayutthaya. Please check API request.
[2025-03-30T12:31:53.482+0000] {logging_mixin.py:190} INFO - Task instance in failure state
[2025-03-30T12:31:53.483+0000] {logging_mixin.py:190} INFO - Task start:2025-03-30 12:31:53.237806+00:00 end:2025-03-30 12:31:53.482215+00:00 duration:0.244409
[2025-03-30T12:31:53.484+0000] {logging_mixin.py:190} INFO - Task:<Task(PythonOperator): validate_aqi_data_Ayutthaya> dag:<DAG: aqi_etl_pipeline> dagrun:<DagRun aqi_etl_pipeline @ 2025-03-30 12:20:58.350966+00:00: manual__2025-03-30T12:20:58.350966+00:00, state:running, queued_at: 2025-03-30 12:20:58.371761+00:00. externally triggered: True>
[2025-03-30T12:31:53.484+0000] {logging_mixin.py:190} INFO - Failure caused by Missing data file for Ayutthaya. Please check API request.
[2025-03-30T12:31:53.485+0000] {taskinstance.py:1225} INFO - Marking task as UP_FOR_RETRY. dag_id=aqi_etl_pipeline, task_id=validate_aqi_data_Ayutthaya, run_id=manual__2025-03-30T12:20:58.350966+00:00, execution_date=20250330T122058, start_date=20250330T123153, end_date=20250330T123153
[2025-03-30T12:31:53.496+0000] {taskinstance.py:340} INFO - ::group::Post task execution logs
[2025-03-30T12:31:53.497+0000] {standard_task_runner.py:124} ERROR - Failed to execute job 613 for task validate_aqi_data_Ayutthaya (Missing data file for Ayutthaya. Please check API request.; 31808)
Traceback (most recent call last):
  File "/opt/airflow/dags/api_etl_pipeline.py", line 74, in _validate_aqi_data
    with open(f"{DAG_FOLDER}/aqi_data_{city}.json", "r") as f:
         ^^^^^^^^^^^^^^^^^^^^^^^^^^^^^^^^^^^^^^^^^^^^^^^
FileNotFoundError: [Errno 2] No such file or directory: '/opt/airflow/dags/aqi_data_Ayutthaya.json'

During handling of the above exception, another exception occurred:

Traceback (most recent call last):
  File "/home/airflow/.local/lib/python3.12/site-packages/airflow/task/task_runner/standard_task_runner.py", line 117, in _start_by_fork
    ret = args.func(args, dag=self.dag)
          ^^^^^^^^^^^^^^^^^^^^^^^^^^^^^
  File "/home/airflow/.local/lib/python3.12/site-packages/airflow/cli/cli_config.py", line 49, in command
    return func(*args, **kwargs)
           ^^^^^^^^^^^^^^^^^^^^^
  File "/home/airflow/.local/lib/python3.12/site-packages/airflow/utils/cli.py", line 116, in wrapper
    return f(*args, **kwargs)
           ^^^^^^^^^^^^^^^^^^
  File "/home/airflow/.local/lib/python3.12/site-packages/airflow/cli/commands/task_command.py", line 483, in task_run
    task_return_code = _run_task_by_selected_method(args, _dag, ti)
                       ^^^^^^^^^^^^^^^^^^^^^^^^^^^^^^^^^^^^^^^^^^^^
  File "/home/airflow/.local/lib/python3.12/site-packages/airflow/cli/commands/task_command.py", line 256, in _run_task_by_selected_method
    return _run_raw_task(args, ti)
           ^^^^^^^^^^^^^^^^^^^^^^^
  File "/home/airflow/.local/lib/python3.12/site-packages/airflow/cli/commands/task_command.py", line 341, in _run_raw_task
    return ti._run_raw_task(
           ^^^^^^^^^^^^^^^^^
  File "/home/airflow/.local/lib/python3.12/site-packages/airflow/utils/session.py", line 97, in wrapper
    return func(*args, session=session, **kwargs)
           ^^^^^^^^^^^^^^^^^^^^^^^^^^^^^^^^^^^^^^
  File "/home/airflow/.local/lib/python3.12/site-packages/airflow/models/taskinstance.py", line 3005, in _run_raw_task
    return _run_raw_task(
           ^^^^^^^^^^^^^^
  File "/home/airflow/.local/lib/python3.12/site-packages/airflow/models/taskinstance.py", line 273, in _run_raw_task
    TaskInstance._execute_task_with_callbacks(
  File "/home/airflow/.local/lib/python3.12/site-packages/airflow/models/taskinstance.py", line 3159, in _execute_task_with_callbacks
    result = self._execute_task(context, task_orig)
             ^^^^^^^^^^^^^^^^^^^^^^^^^^^^^^^^^^^^^^
  File "/home/airflow/.local/lib/python3.12/site-packages/airflow/models/taskinstance.py", line 3183, in _execute_task
    return _execute_task(self, context, task_orig)
           ^^^^^^^^^^^^^^^^^^^^^^^^^^^^^^^^^^^^^^^
  File "/home/airflow/.local/lib/python3.12/site-packages/airflow/models/taskinstance.py", line 767, in _execute_task
    result = _execute_callable(context=context, **execute_callable_kwargs)
             ^^^^^^^^^^^^^^^^^^^^^^^^^^^^^^^^^^^^^^^^^^^^^^^^^^^^^^^^^^^^^
  File "/home/airflow/.local/lib/python3.12/site-packages/airflow/models/taskinstance.py", line 733, in _execute_callable
    return ExecutionCallableRunner(
           ^^^^^^^^^^^^^^^^^^^^^^^^
  File "/home/airflow/.local/lib/python3.12/site-packages/airflow/utils/operator_helpers.py", line 252, in run
    return self.func(*args, **kwargs)
           ^^^^^^^^^^^^^^^^^^^^^^^^^^
  File "/home/airflow/.local/lib/python3.12/site-packages/airflow/models/baseoperator.py", line 422, in wrapper
    return func(self, *args, **kwargs)
           ^^^^^^^^^^^^^^^^^^^^^^^^^^^
  File "/home/airflow/.local/lib/python3.12/site-packages/airflow/operators/python.py", line 238, in execute
    return_value = self.execute_callable()
                   ^^^^^^^^^^^^^^^^^^^^^^^
  File "/home/airflow/.local/lib/python3.12/site-packages/airflow/operators/python.py", line 256, in execute_callable
    return runner.run(*self.op_args, **self.op_kwargs)
           ^^^^^^^^^^^^^^^^^^^^^^^^^^^^^^^^^^^^^^^^^^^
  File "/home/airflow/.local/lib/python3.12/site-packages/airflow/utils/operator_helpers.py", line 252, in run
    return self.func(*args, **kwargs)
           ^^^^^^^^^^^^^^^^^^^^^^^^^^
  File "/opt/airflow/dags/api_etl_pipeline.py", line 106, in _validate_aqi_data
    raise ValueError(f"Missing data file for {city}. Please check API request.")
ValueError: Missing data file for Ayutthaya. Please check API request.
[2025-03-30T12:31:53.549+0000] {local_task_job_runner.py:266} INFO - Task exited with return code 1
[2025-03-30T12:31:53.584+0000] {taskinstance.py:3895} INFO - 0 downstream tasks scheduled from follow-on schedule check
[2025-03-30T12:31:53.586+0000] {local_task_job_runner.py:245} INFO - ::endgroup::
