[2025-03-20T07:30:22.972+0000] {local_task_job_runner.py:123} INFO - ::group::Pre task execution logs
[2025-03-20T07:30:23.060+0000] {taskinstance.py:2613} INFO - Dependencies all met for dep_context=non-requeueable deps ti=<TaskInstance: aqi_etl_pipeline.get_aqi_data scheduled__2025-03-19T00:00:00+00:00 [queued]>
[2025-03-20T07:30:23.094+0000] {taskinstance.py:2613} INFO - Dependencies all met for dep_context=requeueable deps ti=<TaskInstance: aqi_etl_pipeline.get_aqi_data scheduled__2025-03-19T00:00:00+00:00 [queued]>
[2025-03-20T07:30:23.098+0000] {taskinstance.py:2866} INFO - Starting attempt 1 of 1
[2025-03-20T07:30:23.156+0000] {taskinstance.py:2889} INFO - Executing <Task(PythonOperator): get_aqi_data> on 2025-03-19 00:00:00+00:00
[2025-03-20T07:30:23.206+0000] {standard_task_runner.py:104} INFO - Running: ['***', 'tasks', 'run', 'aqi_etl_pipeline', 'get_aqi_data', 'scheduled__2025-03-19T00:00:00+00:00', '--job-id', '16', '--raw', '--subdir', 'DAGS_FOLDER/api_etl_pipeline.py', '--cfg-path', '/tmp/tmp0p0ztckb']
[2025-03-20T07:30:23.214+0000] {standard_task_runner.py:105} INFO - Job 16: Subtask get_aqi_data
[2025-03-20T07:30:23.231+0000] {logging_mixin.py:190} WARNING - /home/***/.local/lib/python3.12/site-packages/***/task/task_runner/standard_task_runner.py:70 DeprecationWarning: This process (pid=231) is multi-threaded, use of fork() may lead to deadlocks in the child.
[2025-03-20T07:30:23.243+0000] {standard_task_runner.py:72} INFO - Started process 337 to run task
[2025-03-20T07:30:23.357+0000] {task_command.py:467} INFO - Running <TaskInstance: aqi_etl_pipeline.get_aqi_data scheduled__2025-03-19T00:00:00+00:00 [running]> on host b07fc0dab10d
[2025-03-20T07:30:23.545+0000] {taskinstance.py:3132} INFO - Exporting env vars: AIRFLOW_CTX_DAG_OWNER='***' AIRFLOW_CTX_DAG_ID='aqi_etl_pipeline' AIRFLOW_CTX_TASK_ID='get_aqi_data' AIRFLOW_CTX_EXECUTION_DATE='2025-03-19T00:00:00+00:00' AIRFLOW_CTX_TRY_NUMBER='1' AIRFLOW_CTX_DAG_RUN_ID='scheduled__2025-03-19T00:00:00+00:00'
[2025-03-20T07:30:23.550+0000] {logging_mixin.py:190} INFO - Task instance is in running state
[2025-03-20T07:30:23.550+0000] {logging_mixin.py:190} INFO -  Previous state of the Task instance: queued
[2025-03-20T07:30:23.552+0000] {logging_mixin.py:190} INFO - Current task name:get_aqi_data state:running start_date:2025-03-20 07:30:23.062168+00:00
[2025-03-20T07:30:23.553+0000] {logging_mixin.py:190} INFO - Dag name:aqi_etl_pipeline and current dag run status:running
[2025-03-20T07:30:23.553+0000] {taskinstance.py:731} INFO - ::endgroup::
[2025-03-20T07:30:24.253+0000] {logging_mixin.py:190} INFO - https://api.airvisual.com/v2/city?city=Bangkok&state=Bangkok&country=Thailand&key=***
[2025-03-20T07:30:24.259+0000] {logging_mixin.py:190} INFO - {'status': 'success', 'data': {'city': 'Bangkok', 'state': 'Bangkok', 'country': 'Thailand', 'location': {'type': 'Point', 'coordinates': [100.4888394, 13.7292915]}, 'current': {'pollution': {'ts': '2025-03-20T07:00:00.000Z', 'aqius': 109, 'mainus': 'p2', 'aqicn': 71, 'maincn': 'p1'}, 'weather': {'ts': '2025-03-20T07:00:00.000Z', 'tp': 34, 'pr': 1013, 'hu': 37, 'ws': 2.65, 'wd': 58, 'ic': '04d'}}}}
[2025-03-20T07:30:24.260+0000] {taskinstance.py:3311} ERROR - Task failed with exception
Traceback (most recent call last):
  File "/home/airflow/.local/lib/python3.12/site-packages/airflow/models/taskinstance.py", line 767, in _execute_task
    result = _execute_callable(context=context, **execute_callable_kwargs)
             ^^^^^^^^^^^^^^^^^^^^^^^^^^^^^^^^^^^^^^^^^^^^^^^^^^^^^^^^^^^^^
  File "/home/airflow/.local/lib/python3.12/site-packages/airflow/models/taskinstance.py", line 733, in _execute_callable
    return ExecutionCallableRunner(
           ^^^^^^^^^^^^^^^^^^^^^^^^
  File "/home/airflow/.local/lib/python3.12/site-packages/airflow/utils/operator_helpers.py", line 252, in run
    return self.func(*args, **kwargs)
           ^^^^^^^^^^^^^^^^^^^^^^^^^^
  File "/home/airflow/.local/lib/python3.12/site-packages/airflow/models/baseoperator.py", line 422, in wrapper
    return func(self, *args, **kwargs)
           ^^^^^^^^^^^^^^^^^^^^^^^^^^^
  File "/home/airflow/.local/lib/python3.12/site-packages/airflow/operators/python.py", line 238, in execute
    return_value = self.execute_callable()
                   ^^^^^^^^^^^^^^^^^^^^^^^
  File "/home/airflow/.local/lib/python3.12/site-packages/airflow/operators/python.py", line 256, in execute_callable
    return runner.run(*self.op_args, **self.op_kwargs)
           ^^^^^^^^^^^^^^^^^^^^^^^^^^^^^^^^^^^^^^^^^^^
  File "/home/airflow/.local/lib/python3.12/site-packages/airflow/utils/operator_helpers.py", line 252, in run
    return self.func(*args, **kwargs)
           ^^^^^^^^^^^^^^^^^^^^^^^^^^
  File "/opt/airflow/dags/api_etl_pipeline.py", line 37, in _get_aqi_data
    with open(f"{DAG_FOLDER}/aqi_data.json", "w") as f:
         ^^^^^^^^^^^^^^^^^^^^^^^^^^^^^^^^^^^^^^^^
NotADirectoryError: [Errno 20] Not a directory: '/opt/airflow/dags/api_etl_pipeline.py/aqi_data.json'
[2025-03-20T07:30:24.280+0000] {logging_mixin.py:190} INFO - Task instance in failure state
[2025-03-20T07:30:24.283+0000] {logging_mixin.py:190} INFO - Task start:2025-03-20 07:30:23.062168+00:00 end:2025-03-20 07:30:24.280402+00:00 duration:1.218234
[2025-03-20T07:30:24.283+0000] {logging_mixin.py:190} INFO - Task:<Task(PythonOperator): get_aqi_data> dag:<DAG: aqi_etl_pipeline> dagrun:<DagRun aqi_etl_pipeline @ 2025-03-19 00:00:00+00:00: scheduled__2025-03-19T00:00:00+00:00, state:running, queued_at: 2025-03-20 07:30:11.373209+00:00. externally triggered: False>
[2025-03-20T07:30:24.283+0000] {logging_mixin.py:190} INFO - Failure caused by [Errno 20] Not a directory: '/opt/***/dags/api_etl_pipeline.py/aqi_data.json'
[2025-03-20T07:30:24.284+0000] {taskinstance.py:1225} INFO - Marking task as FAILED. dag_id=aqi_etl_pipeline, task_id=get_aqi_data, run_id=scheduled__2025-03-19T00:00:00+00:00, execution_date=20250319T000000, start_date=20250320T073023, end_date=20250320T073024
[2025-03-20T07:30:24.311+0000] {taskinstance.py:340} INFO - ::group::Post task execution logs
[2025-03-20T07:30:24.313+0000] {standard_task_runner.py:124} ERROR - Failed to execute job 16 for task get_aqi_data ([Errno 20] Not a directory: '/opt/airflow/dags/api_etl_pipeline.py/aqi_data.json'; 337)
Traceback (most recent call last):
  File "/home/airflow/.local/lib/python3.12/site-packages/airflow/task/task_runner/standard_task_runner.py", line 117, in _start_by_fork
    ret = args.func(args, dag=self.dag)
          ^^^^^^^^^^^^^^^^^^^^^^^^^^^^^
  File "/home/airflow/.local/lib/python3.12/site-packages/airflow/cli/cli_config.py", line 49, in command
    return func(*args, **kwargs)
           ^^^^^^^^^^^^^^^^^^^^^
  File "/home/airflow/.local/lib/python3.12/site-packages/airflow/utils/cli.py", line 116, in wrapper
    return f(*args, **kwargs)
           ^^^^^^^^^^^^^^^^^^
  File "/home/airflow/.local/lib/python3.12/site-packages/airflow/cli/commands/task_command.py", line 483, in task_run
    task_return_code = _run_task_by_selected_method(args, _dag, ti)
                       ^^^^^^^^^^^^^^^^^^^^^^^^^^^^^^^^^^^^^^^^^^^^
  File "/home/airflow/.local/lib/python3.12/site-packages/airflow/cli/commands/task_command.py", line 256, in _run_task_by_selected_method
    return _run_raw_task(args, ti)
           ^^^^^^^^^^^^^^^^^^^^^^^
  File "/home/airflow/.local/lib/python3.12/site-packages/airflow/cli/commands/task_command.py", line 341, in _run_raw_task
    return ti._run_raw_task(
           ^^^^^^^^^^^^^^^^^
  File "/home/airflow/.local/lib/python3.12/site-packages/airflow/utils/session.py", line 97, in wrapper
    return func(*args, session=session, **kwargs)
           ^^^^^^^^^^^^^^^^^^^^^^^^^^^^^^^^^^^^^^
  File "/home/airflow/.local/lib/python3.12/site-packages/airflow/models/taskinstance.py", line 3005, in _run_raw_task
    return _run_raw_task(
           ^^^^^^^^^^^^^^
  File "/home/airflow/.local/lib/python3.12/site-packages/airflow/models/taskinstance.py", line 273, in _run_raw_task
    TaskInstance._execute_task_with_callbacks(
  File "/home/airflow/.local/lib/python3.12/site-packages/airflow/models/taskinstance.py", line 3159, in _execute_task_with_callbacks
    result = self._execute_task(context, task_orig)
             ^^^^^^^^^^^^^^^^^^^^^^^^^^^^^^^^^^^^^^
  File "/home/airflow/.local/lib/python3.12/site-packages/airflow/models/taskinstance.py", line 3183, in _execute_task
    return _execute_task(self, context, task_orig)
           ^^^^^^^^^^^^^^^^^^^^^^^^^^^^^^^^^^^^^^^
  File "/home/airflow/.local/lib/python3.12/site-packages/airflow/models/taskinstance.py", line 767, in _execute_task
    result = _execute_callable(context=context, **execute_callable_kwargs)
             ^^^^^^^^^^^^^^^^^^^^^^^^^^^^^^^^^^^^^^^^^^^^^^^^^^^^^^^^^^^^^
  File "/home/airflow/.local/lib/python3.12/site-packages/airflow/models/taskinstance.py", line 733, in _execute_callable
    return ExecutionCallableRunner(
           ^^^^^^^^^^^^^^^^^^^^^^^^
  File "/home/airflow/.local/lib/python3.12/site-packages/airflow/utils/operator_helpers.py", line 252, in run
    return self.func(*args, **kwargs)
           ^^^^^^^^^^^^^^^^^^^^^^^^^^
  File "/home/airflow/.local/lib/python3.12/site-packages/airflow/models/baseoperator.py", line 422, in wrapper
    return func(self, *args, **kwargs)
           ^^^^^^^^^^^^^^^^^^^^^^^^^^^
  File "/home/airflow/.local/lib/python3.12/site-packages/airflow/operators/python.py", line 238, in execute
    return_value = self.execute_callable()
                   ^^^^^^^^^^^^^^^^^^^^^^^
  File "/home/airflow/.local/lib/python3.12/site-packages/airflow/operators/python.py", line 256, in execute_callable
    return runner.run(*self.op_args, **self.op_kwargs)
           ^^^^^^^^^^^^^^^^^^^^^^^^^^^^^^^^^^^^^^^^^^^
  File "/home/airflow/.local/lib/python3.12/site-packages/airflow/utils/operator_helpers.py", line 252, in run
    return self.func(*args, **kwargs)
           ^^^^^^^^^^^^^^^^^^^^^^^^^^
  File "/opt/airflow/dags/api_etl_pipeline.py", line 37, in _get_aqi_data
    with open(f"{DAG_FOLDER}/aqi_data.json", "w") as f:
         ^^^^^^^^^^^^^^^^^^^^^^^^^^^^^^^^^^^^^^^^
NotADirectoryError: [Errno 20] Not a directory: '/opt/airflow/dags/api_etl_pipeline.py/aqi_data.json'
[2025-03-20T07:30:24.348+0000] {local_task_job_runner.py:266} INFO - Task exited with return code 1
[2025-03-20T07:30:24.397+0000] {taskinstance.py:3895} INFO - 0 downstream tasks scheduled from follow-on schedule check
[2025-03-20T07:30:24.407+0000] {local_task_job_runner.py:245} INFO - ::endgroup::
[2025-03-23T08:13:59.841+0000] {local_task_job_runner.py:123} INFO - ::group::Pre task execution logs
[2025-03-23T08:14:00.007+0000] {taskinstance.py:2613} INFO - Dependencies all met for dep_context=non-requeueable deps ti=<TaskInstance: aqi_etl_pipeline.get_aqi_data scheduled__2025-03-19T00:00:00+00:00 [queued]>
[2025-03-23T08:14:00.091+0000] {taskinstance.py:2613} INFO - Dependencies all met for dep_context=requeueable deps ti=<TaskInstance: aqi_etl_pipeline.get_aqi_data scheduled__2025-03-19T00:00:00+00:00 [queued]>
[2025-03-23T08:14:00.095+0000] {taskinstance.py:2866} INFO - Starting attempt 1 of 1
[2025-03-23T08:14:00.231+0000] {taskinstance.py:2889} INFO - Executing <Task(PythonOperator): get_aqi_data> on 2025-03-19 00:00:00+00:00
[2025-03-23T08:14:00.395+0000] {logging_mixin.py:190} WARNING - /home/***/.local/lib/python3.12/site-packages/***/task/task_runner/standard_task_runner.py:70 DeprecationWarning: This process (pid=30072) is multi-threaded, use of fork() may lead to deadlocks in the child.
[2025-03-23T08:14:00.418+0000] {standard_task_runner.py:72} INFO - Started process 30151 to run task
[2025-03-23T08:14:00.373+0000] {standard_task_runner.py:104} INFO - Running: ['***', 'tasks', 'run', 'aqi_etl_pipeline', 'get_aqi_data', 'scheduled__2025-03-19T00:00:00+00:00', '--job-id', '240', '--raw', '--subdir', 'DAGS_FOLDER/api_etl_pipeline.py', '--cfg-path', '/tmp/tmpm_4fleia']
[2025-03-23T08:14:00.431+0000] {standard_task_runner.py:105} INFO - Job 240: Subtask get_aqi_data
[2025-03-23T08:14:00.894+0000] {task_command.py:467} INFO - Running <TaskInstance: aqi_etl_pipeline.get_aqi_data scheduled__2025-03-19T00:00:00+00:00 [running]> on host ed55a332e3f9
[2025-03-23T08:14:01.858+0000] {taskinstance.py:3132} INFO - Exporting env vars: AIRFLOW_CTX_DAG_OWNER='***' AIRFLOW_CTX_DAG_ID='aqi_etl_pipeline' AIRFLOW_CTX_TASK_ID='get_aqi_data' AIRFLOW_CTX_EXECUTION_DATE='2025-03-19T00:00:00+00:00' AIRFLOW_CTX_TRY_NUMBER='1' AIRFLOW_CTX_DAG_RUN_ID='scheduled__2025-03-19T00:00:00+00:00'
[2025-03-23T08:14:01.859+0000] {logging_mixin.py:190} INFO - Task instance is in running state
[2025-03-23T08:14:01.871+0000] {logging_mixin.py:190} INFO -  Previous state of the Task instance: queued
[2025-03-23T08:14:01.871+0000] {logging_mixin.py:190} INFO - Current task name:get_aqi_data state:running start_date:2025-03-23 08:14:00.009318+00:00
[2025-03-23T08:14:01.872+0000] {logging_mixin.py:190} INFO - Dag name:aqi_etl_pipeline and current dag run status:running
[2025-03-23T08:14:01.873+0000] {taskinstance.py:731} INFO - ::endgroup::
[2025-03-23T08:14:02.831+0000] {logging_mixin.py:190} INFO - https://api.airvisual.com/v2/city?city=Bangkok&state=Bangkok&country=Thailand&key=***
[2025-03-23T08:14:02.850+0000] {logging_mixin.py:190} INFO - {'status': 'fail', 'data': {'message': 'Too Many Requests'}}
[2025-03-23T08:14:02.874+0000] {python.py:240} INFO - Done. Returned value was: None
[2025-03-23T08:14:02.934+0000] {taskinstance.py:340} INFO - ::group::Post task execution logs
[2025-03-23T08:14:02.934+0000] {taskinstance.py:352} INFO - Marking task as SUCCESS. dag_id=aqi_etl_pipeline, task_id=get_aqi_data, run_id=scheduled__2025-03-19T00:00:00+00:00, execution_date=20250319T000000, start_date=20250323T081400, end_date=20250323T081402
[2025-03-23T08:14:03.907+0000] {logging_mixin.py:190} INFO - Task instance in success state
[2025-03-23T08:14:03.908+0000] {logging_mixin.py:190} INFO -  Previous state of the Task instance: running
[2025-03-23T08:14:03.915+0000] {logging_mixin.py:190} INFO - Dag name:aqi_etl_pipeline queued_at:2025-03-23 08:13:35.122546+00:00
[2025-03-23T08:14:03.921+0000] {logging_mixin.py:190} INFO - Task hostname:ed55a332e3f9 operator:PythonOperator
[2025-03-23T08:14:04.184+0000] {local_task_job_runner.py:266} INFO - Task exited with return code 0
[2025-03-23T08:14:04.633+0000] {taskinstance.py:3895} INFO - 1 downstream tasks scheduled from follow-on schedule check
[2025-03-23T08:14:04.661+0000] {local_task_job_runner.py:245} INFO - ::endgroup::
