[2025-03-31T07:13:31.880+0000] {local_task_job_runner.py:123} INFO - ::group::Pre task execution logs
[2025-03-31T07:13:31.893+0000] {taskinstance.py:2613} INFO - Dependencies all met for dep_context=non-requeueable deps ti=<TaskInstance: aqi_etl_pipeline.aqi_tasks_group.get_aqi_data_Nakhon_Pathom manual__2025-03-31T07:02:31.512459+00:00 [queued]>
[2025-03-31T07:13:31.901+0000] {taskinstance.py:2613} INFO - Dependencies all met for dep_context=requeueable deps ti=<TaskInstance: aqi_etl_pipeline.aqi_tasks_group.get_aqi_data_Nakhon_Pathom manual__2025-03-31T07:02:31.512459+00:00 [queued]>
[2025-03-31T07:13:31.901+0000] {taskinstance.py:2866} INFO - Starting attempt 1 of 4
[2025-03-31T07:13:31.911+0000] {taskinstance.py:2889} INFO - Executing <Task(PythonOperator): aqi_tasks_group.get_aqi_data_Nakhon_Pathom> on 2025-03-31 07:02:31.512459+00:00
[2025-03-31T07:13:31.922+0000] {standard_task_runner.py:104} INFO - Running: ['***', 'tasks', 'run', 'aqi_etl_pipeline', 'aqi_tasks_group.get_aqi_data_Nakhon_Pathom', 'manual__2025-03-31T07:02:31.512459+00:00', '--job-id', '919', '--raw', '--subdir', 'DAGS_FOLDER/api_etl_pipeline.py', '--cfg-path', '/tmp/tmpfgsfk63l']
[2025-03-31T07:13:31.924+0000] {standard_task_runner.py:105} INFO - Job 919: Subtask aqi_tasks_group.get_aqi_data_Nakhon_Pathom
[2025-03-31T07:13:31.929+0000] {logging_mixin.py:190} WARNING - /home/***/.local/lib/python3.12/site-packages/***/task/task_runner/standard_task_runner.py:70 DeprecationWarning: This process (pid=3764) is multi-threaded, use of fork() may lead to deadlocks in the child.
[2025-03-31T07:13:31.931+0000] {standard_task_runner.py:72} INFO - Started process 3810 to run task
[2025-03-31T07:13:31.963+0000] {task_command.py:467} INFO - Running <TaskInstance: aqi_etl_pipeline.aqi_tasks_group.get_aqi_data_Nakhon_Pathom manual__2025-03-31T07:02:31.512459+00:00 [running]> on host daf74ef548f3
[2025-03-31T07:13:32.033+0000] {taskinstance.py:3132} INFO - Exporting env vars: AIRFLOW_CTX_DAG_OWNER='***' AIRFLOW_CTX_DAG_ID='aqi_etl_pipeline' AIRFLOW_CTX_TASK_ID='aqi_tasks_group.get_aqi_data_Nakhon_Pathom' AIRFLOW_CTX_EXECUTION_DATE='2025-03-31T07:02:31.512459+00:00' AIRFLOW_CTX_TRY_NUMBER='1' AIRFLOW_CTX_DAG_RUN_ID='manual__2025-03-31T07:02:31.512459+00:00'
[2025-03-31T07:13:32.034+0000] {logging_mixin.py:190} INFO - Task instance is in running state
[2025-03-31T07:13:32.035+0000] {logging_mixin.py:190} INFO -  Previous state of the Task instance: queued
[2025-03-31T07:13:32.035+0000] {logging_mixin.py:190} INFO - Current task name:aqi_tasks_group.get_aqi_data_Nakhon_Pathom state:running start_date:2025-03-31 07:13:31.894473+00:00
[2025-03-31T07:13:32.036+0000] {logging_mixin.py:190} INFO - Dag name:aqi_etl_pipeline and current dag run status:running
[2025-03-31T07:13:32.036+0000] {taskinstance.py:731} INFO - ::endgroup::
[2025-03-31T07:13:32.037+0000] {api_etl_pipeline.py:28} INFO - Fetching AQI data with params: {'city': 'Nakhon Pathom', 'state': 'Nonthaburi', 'country': 'Thailand', 'key': '***'}
[2025-03-31T07:13:32.386+0000] {taskinstance.py:3311} ERROR - Task failed with exception
Traceback (most recent call last):
  File "/home/airflow/.local/lib/python3.12/site-packages/airflow/models/taskinstance.py", line 767, in _execute_task
    result = _execute_callable(context=context, **execute_callable_kwargs)
             ^^^^^^^^^^^^^^^^^^^^^^^^^^^^^^^^^^^^^^^^^^^^^^^^^^^^^^^^^^^^^
  File "/home/airflow/.local/lib/python3.12/site-packages/airflow/models/taskinstance.py", line 733, in _execute_callable
    return ExecutionCallableRunner(
           ^^^^^^^^^^^^^^^^^^^^^^^^
  File "/home/airflow/.local/lib/python3.12/site-packages/airflow/utils/operator_helpers.py", line 252, in run
    return self.func(*args, **kwargs)
           ^^^^^^^^^^^^^^^^^^^^^^^^^^
  File "/home/airflow/.local/lib/python3.12/site-packages/airflow/models/baseoperator.py", line 422, in wrapper
    return func(self, *args, **kwargs)
           ^^^^^^^^^^^^^^^^^^^^^^^^^^^
  File "/home/airflow/.local/lib/python3.12/site-packages/airflow/operators/python.py", line 238, in execute
    return_value = self.execute_callable()
                   ^^^^^^^^^^^^^^^^^^^^^^^
  File "/home/airflow/.local/lib/python3.12/site-packages/airflow/operators/python.py", line 256, in execute_callable
    return runner.run(*self.op_args, **self.op_kwargs)
           ^^^^^^^^^^^^^^^^^^^^^^^^^^^^^^^^^^^^^^^^^^^
  File "/home/airflow/.local/lib/python3.12/site-packages/airflow/utils/operator_helpers.py", line 252, in run
    return self.func(*args, **kwargs)
           ^^^^^^^^^^^^^^^^^^^^^^^^^^
  File "/opt/airflow/dags/api_etl_pipeline.py", line 41, in _get_aqi_data
    raise ValueError(f"API Error {response.status_code}: {data.get('data', {}).get('message', 'Unknown error')}")
ValueError: API Error 400: city_not_found
[2025-03-31T07:13:32.402+0000] {logging_mixin.py:190} INFO - Task instance in failure state
[2025-03-31T07:13:32.402+0000] {logging_mixin.py:190} INFO - Task start:2025-03-31 07:13:31.894473+00:00 end:2025-03-31 07:13:32.401637+00:00 duration:0.507164
[2025-03-31T07:13:32.403+0000] {logging_mixin.py:190} INFO - Task:<Task(PythonOperator): aqi_tasks_group.get_aqi_data_Nakhon_Pathom> dag:<DAG: aqi_etl_pipeline> dagrun:<DagRun aqi_etl_pipeline @ 2025-03-31 07:02:31.512459+00:00: manual__2025-03-31T07:02:31.512459+00:00, state:running, queued_at: 2025-03-31 07:02:31.523025+00:00. externally triggered: True>
[2025-03-31T07:13:32.403+0000] {logging_mixin.py:190} INFO - Failure caused by API Error 400: city_not_found
[2025-03-31T07:13:32.403+0000] {taskinstance.py:1225} INFO - Marking task as UP_FOR_RETRY. dag_id=aqi_etl_pipeline, task_id=aqi_tasks_group.get_aqi_data_Nakhon_Pathom, run_id=manual__2025-03-31T07:02:31.512459+00:00, execution_date=20250331T070231, start_date=20250331T071331, end_date=20250331T071332
[2025-03-31T07:13:32.417+0000] {taskinstance.py:340} INFO - ::group::Post task execution logs
[2025-03-31T07:13:32.418+0000] {standard_task_runner.py:124} ERROR - Failed to execute job 919 for task aqi_tasks_group.get_aqi_data_Nakhon_Pathom (API Error 400: city_not_found; 3810)
Traceback (most recent call last):
  File "/home/airflow/.local/lib/python3.12/site-packages/airflow/task/task_runner/standard_task_runner.py", line 117, in _start_by_fork
    ret = args.func(args, dag=self.dag)
          ^^^^^^^^^^^^^^^^^^^^^^^^^^^^^
  File "/home/airflow/.local/lib/python3.12/site-packages/airflow/cli/cli_config.py", line 49, in command
    return func(*args, **kwargs)
           ^^^^^^^^^^^^^^^^^^^^^
  File "/home/airflow/.local/lib/python3.12/site-packages/airflow/utils/cli.py", line 116, in wrapper
    return f(*args, **kwargs)
           ^^^^^^^^^^^^^^^^^^
  File "/home/airflow/.local/lib/python3.12/site-packages/airflow/cli/commands/task_command.py", line 483, in task_run
    task_return_code = _run_task_by_selected_method(args, _dag, ti)
                       ^^^^^^^^^^^^^^^^^^^^^^^^^^^^^^^^^^^^^^^^^^^^
  File "/home/airflow/.local/lib/python3.12/site-packages/airflow/cli/commands/task_command.py", line 256, in _run_task_by_selected_method
    return _run_raw_task(args, ti)
           ^^^^^^^^^^^^^^^^^^^^^^^
  File "/home/airflow/.local/lib/python3.12/site-packages/airflow/cli/commands/task_command.py", line 341, in _run_raw_task
    return ti._run_raw_task(
           ^^^^^^^^^^^^^^^^^
  File "/home/airflow/.local/lib/python3.12/site-packages/airflow/utils/session.py", line 97, in wrapper
    return func(*args, session=session, **kwargs)
           ^^^^^^^^^^^^^^^^^^^^^^^^^^^^^^^^^^^^^^
  File "/home/airflow/.local/lib/python3.12/site-packages/airflow/models/taskinstance.py", line 3005, in _run_raw_task
    return _run_raw_task(
           ^^^^^^^^^^^^^^
  File "/home/airflow/.local/lib/python3.12/site-packages/airflow/models/taskinstance.py", line 273, in _run_raw_task
    TaskInstance._execute_task_with_callbacks(
  File "/home/airflow/.local/lib/python3.12/site-packages/airflow/models/taskinstance.py", line 3159, in _execute_task_with_callbacks
    result = self._execute_task(context, task_orig)
             ^^^^^^^^^^^^^^^^^^^^^^^^^^^^^^^^^^^^^^
  File "/home/airflow/.local/lib/python3.12/site-packages/airflow/models/taskinstance.py", line 3183, in _execute_task
    return _execute_task(self, context, task_orig)
           ^^^^^^^^^^^^^^^^^^^^^^^^^^^^^^^^^^^^^^^
  File "/home/airflow/.local/lib/python3.12/site-packages/airflow/models/taskinstance.py", line 767, in _execute_task
    result = _execute_callable(context=context, **execute_callable_kwargs)
             ^^^^^^^^^^^^^^^^^^^^^^^^^^^^^^^^^^^^^^^^^^^^^^^^^^^^^^^^^^^^^
  File "/home/airflow/.local/lib/python3.12/site-packages/airflow/models/taskinstance.py", line 733, in _execute_callable
    return ExecutionCallableRunner(
           ^^^^^^^^^^^^^^^^^^^^^^^^
  File "/home/airflow/.local/lib/python3.12/site-packages/airflow/utils/operator_helpers.py", line 252, in run
    return self.func(*args, **kwargs)
           ^^^^^^^^^^^^^^^^^^^^^^^^^^
  File "/home/airflow/.local/lib/python3.12/site-packages/airflow/models/baseoperator.py", line 422, in wrapper
    return func(self, *args, **kwargs)
           ^^^^^^^^^^^^^^^^^^^^^^^^^^^
  File "/home/airflow/.local/lib/python3.12/site-packages/airflow/operators/python.py", line 238, in execute
    return_value = self.execute_callable()
                   ^^^^^^^^^^^^^^^^^^^^^^^
  File "/home/airflow/.local/lib/python3.12/site-packages/airflow/operators/python.py", line 256, in execute_callable
    return runner.run(*self.op_args, **self.op_kwargs)
           ^^^^^^^^^^^^^^^^^^^^^^^^^^^^^^^^^^^^^^^^^^^
  File "/home/airflow/.local/lib/python3.12/site-packages/airflow/utils/operator_helpers.py", line 252, in run
    return self.func(*args, **kwargs)
           ^^^^^^^^^^^^^^^^^^^^^^^^^^
  File "/opt/airflow/dags/api_etl_pipeline.py", line 41, in _get_aqi_data
    raise ValueError(f"API Error {response.status_code}: {data.get('data', {}).get('message', 'Unknown error')}")
ValueError: API Error 400: city_not_found
[2025-03-31T07:13:32.470+0000] {local_task_job_runner.py:266} INFO - Task exited with return code 1
[2025-03-31T07:13:32.488+0000] {taskinstance.py:3895} INFO - 0 downstream tasks scheduled from follow-on schedule check
[2025-03-31T07:13:32.490+0000] {local_task_job_runner.py:245} INFO - ::endgroup::
