[2025-03-30T10:15:28.775+0000] {local_task_job_runner.py:123} INFO - ::group::Pre task execution logs
[2025-03-30T10:15:28.846+0000] {taskinstance.py:2613} INFO - Dependencies all met for dep_context=non-requeueable deps ti=<TaskInstance: aqi_etl_pipeline.validate_aqi_data_Lat_Phrao manual__2025-03-30T10:15:15.399414+00:00 [queued]>
[2025-03-30T10:15:28.876+0000] {taskinstance.py:2613} INFO - Dependencies all met for dep_context=requeueable deps ti=<TaskInstance: aqi_etl_pipeline.validate_aqi_data_Lat_Phrao manual__2025-03-30T10:15:15.399414+00:00 [queued]>
[2025-03-30T10:15:28.879+0000] {taskinstance.py:2866} INFO - Starting attempt 1 of 1
[2025-03-30T10:15:28.950+0000] {taskinstance.py:2889} INFO - Executing <Task(PythonOperator): validate_aqi_data_Lat_Phrao> on 2025-03-30 10:15:15.399414+00:00
[2025-03-30T10:15:29.019+0000] {standard_task_runner.py:104} INFO - Running: ['***', 'tasks', 'run', 'aqi_etl_pipeline', 'validate_aqi_data_Lat_Phrao', 'manual__2025-03-30T10:15:15.399414+00:00', '--job-id', '455', '--raw', '--subdir', 'DAGS_FOLDER/api_etl_pipeline.py', '--cfg-path', '/tmp/tmpwaggxwk5']
[2025-03-30T10:15:29.026+0000] {standard_task_runner.py:105} INFO - Job 455: Subtask validate_aqi_data_Lat_Phrao
[2025-03-30T10:15:29.017+0000] {logging_mixin.py:190} WARNING - /home/***/.local/lib/python3.12/site-packages/***/task/task_runner/standard_task_runner.py:70 DeprecationWarning: This process (pid=38966) is multi-threaded, use of fork() may lead to deadlocks in the child.
[2025-03-30T10:15:29.027+0000] {standard_task_runner.py:72} INFO - Started process 39035 to run task
[2025-03-30T10:15:29.211+0000] {task_command.py:467} INFO - Running <TaskInstance: aqi_etl_pipeline.validate_aqi_data_Lat_Phrao manual__2025-03-30T10:15:15.399414+00:00 [running]> on host 58b9640d9ecf
[2025-03-30T10:15:29.621+0000] {taskinstance.py:3132} INFO - Exporting env vars: AIRFLOW_CTX_DAG_OWNER='***' AIRFLOW_CTX_DAG_ID='aqi_etl_pipeline' AIRFLOW_CTX_TASK_ID='validate_aqi_data_Lat_Phrao' AIRFLOW_CTX_EXECUTION_DATE='2025-03-30T10:15:15.399414+00:00' AIRFLOW_CTX_TRY_NUMBER='1' AIRFLOW_CTX_DAG_RUN_ID='manual__2025-03-30T10:15:15.399414+00:00'
[2025-03-30T10:15:29.631+0000] {logging_mixin.py:190} INFO - Task instance is in running state
[2025-03-30T10:15:29.634+0000] {logging_mixin.py:190} INFO -  Previous state of the Task instance: queued
[2025-03-30T10:15:29.636+0000] {logging_mixin.py:190} INFO - Current task name:validate_aqi_data_Lat_Phrao state:running start_date:2025-03-30 10:15:28.846936+00:00
[2025-03-30T10:15:29.638+0000] {logging_mixin.py:190} INFO - Dag name:aqi_etl_pipeline and current dag run status:running
[2025-03-30T10:15:29.639+0000] {taskinstance.py:731} INFO - ::endgroup::
[2025-03-30T10:15:29.641+0000] {logging_mixin.py:190} INFO - ✅ Validating data for Lat_Phrao: {
  "status": "fail",
  "data": {
    "message": "city_not_found"
  }
}
[2025-03-30T10:15:29.648+0000] {logging_mixin.py:190} INFO - ❌ Value Error in Lat_Phrao: City Lat_Phrao not found in AirVisual API data.
[2025-03-30T10:15:29.650+0000] {taskinstance.py:3311} ERROR - Task failed with exception
Traceback (most recent call last):
  File "/home/airflow/.local/lib/python3.12/site-packages/airflow/models/taskinstance.py", line 767, in _execute_task
    result = _execute_callable(context=context, **execute_callable_kwargs)
             ^^^^^^^^^^^^^^^^^^^^^^^^^^^^^^^^^^^^^^^^^^^^^^^^^^^^^^^^^^^^^
  File "/home/airflow/.local/lib/python3.12/site-packages/airflow/models/taskinstance.py", line 733, in _execute_callable
    return ExecutionCallableRunner(
           ^^^^^^^^^^^^^^^^^^^^^^^^
  File "/home/airflow/.local/lib/python3.12/site-packages/airflow/utils/operator_helpers.py", line 252, in run
    return self.func(*args, **kwargs)
           ^^^^^^^^^^^^^^^^^^^^^^^^^^
  File "/home/airflow/.local/lib/python3.12/site-packages/airflow/models/baseoperator.py", line 422, in wrapper
    return func(self, *args, **kwargs)
           ^^^^^^^^^^^^^^^^^^^^^^^^^^^
  File "/home/airflow/.local/lib/python3.12/site-packages/airflow/operators/python.py", line 238, in execute
    return_value = self.execute_callable()
                   ^^^^^^^^^^^^^^^^^^^^^^^
  File "/home/airflow/.local/lib/python3.12/site-packages/airflow/operators/python.py", line 256, in execute_callable
    return runner.run(*self.op_args, **self.op_kwargs)
           ^^^^^^^^^^^^^^^^^^^^^^^^^^^^^^^^^^^^^^^^^^^
  File "/home/airflow/.local/lib/python3.12/site-packages/airflow/utils/operator_helpers.py", line 252, in run
    return self.func(*args, **kwargs)
           ^^^^^^^^^^^^^^^^^^^^^^^^^^
  File "/opt/airflow/dags/api_etl_pipeline.py", line 73, in _validate_aqi_data
    raise ValueError(f"City {city} not found in AirVisual API data.")
ValueError: City Lat_Phrao not found in AirVisual API data.
[2025-03-30T10:15:29.718+0000] {logging_mixin.py:190} INFO - Task instance in failure state
[2025-03-30T10:15:29.732+0000] {logging_mixin.py:190} INFO - Task start:2025-03-30 10:15:28.846936+00:00 end:2025-03-30 10:15:29.718209+00:00 duration:0.871273
[2025-03-30T10:15:29.739+0000] {logging_mixin.py:190} INFO - Task:<Task(PythonOperator): validate_aqi_data_Lat_Phrao> dag:<DAG: aqi_etl_pipeline> dagrun:<DagRun aqi_etl_pipeline @ 2025-03-30 10:15:15.399414+00:00: manual__2025-03-30T10:15:15.399414+00:00, state:running, queued_at: 2025-03-30 10:15:15.406219+00:00. externally triggered: True>
[2025-03-30T10:15:29.739+0000] {logging_mixin.py:190} INFO - Failure caused by City Lat_Phrao not found in AirVisual API data.
[2025-03-30T10:15:29.739+0000] {taskinstance.py:1225} INFO - Marking task as FAILED. dag_id=aqi_etl_pipeline, task_id=validate_aqi_data_Lat_Phrao, run_id=manual__2025-03-30T10:15:15.399414+00:00, execution_date=20250330T101515, start_date=20250330T101528, end_date=20250330T101529
[2025-03-30T10:15:29.799+0000] {taskinstance.py:340} INFO - ::group::Post task execution logs
[2025-03-30T10:15:29.804+0000] {standard_task_runner.py:124} ERROR - Failed to execute job 455 for task validate_aqi_data_Lat_Phrao (City Lat_Phrao not found in AirVisual API data.; 39035)
Traceback (most recent call last):
  File "/home/airflow/.local/lib/python3.12/site-packages/airflow/task/task_runner/standard_task_runner.py", line 117, in _start_by_fork
    ret = args.func(args, dag=self.dag)
          ^^^^^^^^^^^^^^^^^^^^^^^^^^^^^
  File "/home/airflow/.local/lib/python3.12/site-packages/airflow/cli/cli_config.py", line 49, in command
    return func(*args, **kwargs)
           ^^^^^^^^^^^^^^^^^^^^^
  File "/home/airflow/.local/lib/python3.12/site-packages/airflow/utils/cli.py", line 116, in wrapper
    return f(*args, **kwargs)
           ^^^^^^^^^^^^^^^^^^
  File "/home/airflow/.local/lib/python3.12/site-packages/airflow/cli/commands/task_command.py", line 483, in task_run
    task_return_code = _run_task_by_selected_method(args, _dag, ti)
                       ^^^^^^^^^^^^^^^^^^^^^^^^^^^^^^^^^^^^^^^^^^^^
  File "/home/airflow/.local/lib/python3.12/site-packages/airflow/cli/commands/task_command.py", line 256, in _run_task_by_selected_method
    return _run_raw_task(args, ti)
           ^^^^^^^^^^^^^^^^^^^^^^^
  File "/home/airflow/.local/lib/python3.12/site-packages/airflow/cli/commands/task_command.py", line 341, in _run_raw_task
    return ti._run_raw_task(
           ^^^^^^^^^^^^^^^^^
  File "/home/airflow/.local/lib/python3.12/site-packages/airflow/utils/session.py", line 97, in wrapper
    return func(*args, session=session, **kwargs)
           ^^^^^^^^^^^^^^^^^^^^^^^^^^^^^^^^^^^^^^
  File "/home/airflow/.local/lib/python3.12/site-packages/airflow/models/taskinstance.py", line 3005, in _run_raw_task
    return _run_raw_task(
           ^^^^^^^^^^^^^^
  File "/home/airflow/.local/lib/python3.12/site-packages/airflow/models/taskinstance.py", line 273, in _run_raw_task
    TaskInstance._execute_task_with_callbacks(
  File "/home/airflow/.local/lib/python3.12/site-packages/airflow/models/taskinstance.py", line 3159, in _execute_task_with_callbacks
    result = self._execute_task(context, task_orig)
             ^^^^^^^^^^^^^^^^^^^^^^^^^^^^^^^^^^^^^^
  File "/home/airflow/.local/lib/python3.12/site-packages/airflow/models/taskinstance.py", line 3183, in _execute_task
    return _execute_task(self, context, task_orig)
           ^^^^^^^^^^^^^^^^^^^^^^^^^^^^^^^^^^^^^^^
  File "/home/airflow/.local/lib/python3.12/site-packages/airflow/models/taskinstance.py", line 767, in _execute_task
    result = _execute_callable(context=context, **execute_callable_kwargs)
             ^^^^^^^^^^^^^^^^^^^^^^^^^^^^^^^^^^^^^^^^^^^^^^^^^^^^^^^^^^^^^
  File "/home/airflow/.local/lib/python3.12/site-packages/airflow/models/taskinstance.py", line 733, in _execute_callable
    return ExecutionCallableRunner(
           ^^^^^^^^^^^^^^^^^^^^^^^^
  File "/home/airflow/.local/lib/python3.12/site-packages/airflow/utils/operator_helpers.py", line 252, in run
    return self.func(*args, **kwargs)
           ^^^^^^^^^^^^^^^^^^^^^^^^^^
  File "/home/airflow/.local/lib/python3.12/site-packages/airflow/models/baseoperator.py", line 422, in wrapper
    return func(self, *args, **kwargs)
           ^^^^^^^^^^^^^^^^^^^^^^^^^^^
  File "/home/airflow/.local/lib/python3.12/site-packages/airflow/operators/python.py", line 238, in execute
    return_value = self.execute_callable()
                   ^^^^^^^^^^^^^^^^^^^^^^^
  File "/home/airflow/.local/lib/python3.12/site-packages/airflow/operators/python.py", line 256, in execute_callable
    return runner.run(*self.op_args, **self.op_kwargs)
           ^^^^^^^^^^^^^^^^^^^^^^^^^^^^^^^^^^^^^^^^^^^
  File "/home/airflow/.local/lib/python3.12/site-packages/airflow/utils/operator_helpers.py", line 252, in run
    return self.func(*args, **kwargs)
           ^^^^^^^^^^^^^^^^^^^^^^^^^^
  File "/opt/airflow/dags/api_etl_pipeline.py", line 73, in _validate_aqi_data
    raise ValueError(f"City {city} not found in AirVisual API data.")
ValueError: City Lat_Phrao not found in AirVisual API data.
[2025-03-30T10:15:29.951+0000] {local_task_job_runner.py:266} INFO - Task exited with return code 1
[2025-03-30T10:15:30.071+0000] {taskinstance.py:3895} INFO - 0 downstream tasks scheduled from follow-on schedule check
[2025-03-30T10:15:30.079+0000] {local_task_job_runner.py:245} INFO - ::endgroup::
