[2025-03-30T10:03:22.585+0000] {local_task_job_runner.py:123} INFO - ::group::Pre task execution logs
[2025-03-30T10:03:22.640+0000] {taskinstance.py:2613} INFO - Dependencies all met for dep_context=non-requeueable deps ti=<TaskInstance: aqi_etl_pipeline.validate_aqi_data_Pathum_Wan manual__2025-03-30T10:03:09.568060+00:00 [queued]>
[2025-03-30T10:03:22.657+0000] {taskinstance.py:2613} INFO - Dependencies all met for dep_context=requeueable deps ti=<TaskInstance: aqi_etl_pipeline.validate_aqi_data_Pathum_Wan manual__2025-03-30T10:03:09.568060+00:00 [queued]>
[2025-03-30T10:03:22.657+0000] {taskinstance.py:2866} INFO - Starting attempt 1 of 1
[2025-03-30T10:03:22.735+0000] {taskinstance.py:2889} INFO - Executing <Task(PythonOperator): validate_aqi_data_Pathum_Wan> on 2025-03-30 10:03:09.568060+00:00
[2025-03-30T10:03:22.780+0000] {logging_mixin.py:190} WARNING - /home/***/.local/lib/python3.12/site-packages/***/task/task_runner/standard_task_runner.py:70 DeprecationWarning: This process (pid=31884) is multi-threaded, use of fork() may lead to deadlocks in the child.
[2025-03-30T10:03:22.774+0000] {standard_task_runner.py:104} INFO - Running: ['***', 'tasks', 'run', 'aqi_etl_pipeline', 'validate_aqi_data_Pathum_Wan', 'manual__2025-03-30T10:03:09.568060+00:00', '--job-id', '420', '--raw', '--subdir', 'DAGS_FOLDER/api_etl_pipeline.py', '--cfg-path', '/tmp/tmppun4viow']
[2025-03-30T10:03:22.782+0000] {standard_task_runner.py:105} INFO - Job 420: Subtask validate_aqi_data_Pathum_Wan
[2025-03-30T10:03:22.789+0000] {standard_task_runner.py:72} INFO - Started process 31910 to run task
[2025-03-30T10:03:22.928+0000] {task_command.py:467} INFO - Running <TaskInstance: aqi_etl_pipeline.validate_aqi_data_Pathum_Wan manual__2025-03-30T10:03:09.568060+00:00 [running]> on host 58b9640d9ecf
[2025-03-30T10:03:23.101+0000] {taskinstance.py:3132} INFO - Exporting env vars: AIRFLOW_CTX_DAG_OWNER='***' AIRFLOW_CTX_DAG_ID='aqi_etl_pipeline' AIRFLOW_CTX_TASK_ID='validate_aqi_data_Pathum_Wan' AIRFLOW_CTX_EXECUTION_DATE='2025-03-30T10:03:09.568060+00:00' AIRFLOW_CTX_TRY_NUMBER='1' AIRFLOW_CTX_DAG_RUN_ID='manual__2025-03-30T10:03:09.568060+00:00'
[2025-03-30T10:03:23.102+0000] {logging_mixin.py:190} INFO - Task instance is in running state
[2025-03-30T10:03:23.104+0000] {logging_mixin.py:190} INFO -  Previous state of the Task instance: queued
[2025-03-30T10:03:23.105+0000] {logging_mixin.py:190} INFO - Current task name:validate_aqi_data_Pathum_Wan state:running start_date:2025-03-30 10:03:22.643104+00:00
[2025-03-30T10:03:23.105+0000] {logging_mixin.py:190} INFO - Dag name:aqi_etl_pipeline and current dag run status:running
[2025-03-30T10:03:23.105+0000] {taskinstance.py:731} INFO - ::endgroup::
[2025-03-30T10:03:23.106+0000] {logging_mixin.py:190} INFO - ✅ Validating data for Pathum_Wan: {
  "status": "fail",
  "data": {
    "message": "city_not_found"
  }
}
[2025-03-30T10:03:23.106+0000] {logging_mixin.py:190} INFO - ❌ Unexpected error for Pathum_Wan: Invalid data for Pathum_Wan: Missing 'current' key.
[2025-03-30T10:03:23.111+0000] {taskinstance.py:3311} ERROR - Task failed with exception
Traceback (most recent call last):
  File "/opt/airflow/dags/api_etl_pipeline.py", line 65, in _validate_aqi_data
    raise ValueError(f"Invalid data for {city}: Missing 'current' key.")
ValueError: Invalid data for Pathum_Wan: Missing 'current' key.

During handling of the above exception, another exception occurred:

Traceback (most recent call last):
  File "/home/airflow/.local/lib/python3.12/site-packages/airflow/models/taskinstance.py", line 767, in _execute_task
    result = _execute_callable(context=context, **execute_callable_kwargs)
             ^^^^^^^^^^^^^^^^^^^^^^^^^^^^^^^^^^^^^^^^^^^^^^^^^^^^^^^^^^^^^
  File "/home/airflow/.local/lib/python3.12/site-packages/airflow/models/taskinstance.py", line 733, in _execute_callable
    return ExecutionCallableRunner(
           ^^^^^^^^^^^^^^^^^^^^^^^^
  File "/home/airflow/.local/lib/python3.12/site-packages/airflow/utils/operator_helpers.py", line 252, in run
    return self.func(*args, **kwargs)
           ^^^^^^^^^^^^^^^^^^^^^^^^^^
  File "/home/airflow/.local/lib/python3.12/site-packages/airflow/models/baseoperator.py", line 422, in wrapper
    return func(self, *args, **kwargs)
           ^^^^^^^^^^^^^^^^^^^^^^^^^^^
  File "/home/airflow/.local/lib/python3.12/site-packages/airflow/operators/python.py", line 238, in execute
    return_value = self.execute_callable()
                   ^^^^^^^^^^^^^^^^^^^^^^^
  File "/home/airflow/.local/lib/python3.12/site-packages/airflow/operators/python.py", line 256, in execute_callable
    return runner.run(*self.op_args, **self.op_kwargs)
           ^^^^^^^^^^^^^^^^^^^^^^^^^^^^^^^^^^^^^^^^^^^
  File "/home/airflow/.local/lib/python3.12/site-packages/airflow/utils/operator_helpers.py", line 252, in run
    return self.func(*args, **kwargs)
           ^^^^^^^^^^^^^^^^^^^^^^^^^^
  File "/opt/airflow/dags/api_etl_pipeline.py", line 91, in _validate_aqi_data
    raise ValueError(f"Unexpected error for {city}: {str(e)}")
ValueError: Unexpected error for Pathum_Wan: Invalid data for Pathum_Wan: Missing 'current' key.
[2025-03-30T10:03:23.134+0000] {logging_mixin.py:190} INFO - Task instance in failure state
[2025-03-30T10:03:23.136+0000] {logging_mixin.py:190} INFO - Task start:2025-03-30 10:03:22.643104+00:00 end:2025-03-30 10:03:23.134247+00:00 duration:0.491143
[2025-03-30T10:03:23.138+0000] {logging_mixin.py:190} INFO - Task:<Task(PythonOperator): validate_aqi_data_Pathum_Wan> dag:<DAG: aqi_etl_pipeline> dagrun:<DagRun aqi_etl_pipeline @ 2025-03-30 10:03:09.568060+00:00: manual__2025-03-30T10:03:09.568060+00:00, state:running, queued_at: 2025-03-30 10:03:09.577745+00:00. externally triggered: True>
[2025-03-30T10:03:23.139+0000] {logging_mixin.py:190} INFO - Failure caused by Unexpected error for Pathum_Wan: Invalid data for Pathum_Wan: Missing 'current' key.
[2025-03-30T10:03:23.139+0000] {taskinstance.py:1225} INFO - Marking task as FAILED. dag_id=aqi_etl_pipeline, task_id=validate_aqi_data_Pathum_Wan, run_id=manual__2025-03-30T10:03:09.568060+00:00, execution_date=20250330T100309, start_date=20250330T100322, end_date=20250330T100323
[2025-03-30T10:03:23.167+0000] {taskinstance.py:340} INFO - ::group::Post task execution logs
[2025-03-30T10:03:23.170+0000] {standard_task_runner.py:124} ERROR - Failed to execute job 420 for task validate_aqi_data_Pathum_Wan (Unexpected error for Pathum_Wan: Invalid data for Pathum_Wan: Missing 'current' key.; 31910)
Traceback (most recent call last):
  File "/opt/airflow/dags/api_etl_pipeline.py", line 65, in _validate_aqi_data
    raise ValueError(f"Invalid data for {city}: Missing 'current' key.")
ValueError: Invalid data for Pathum_Wan: Missing 'current' key.

During handling of the above exception, another exception occurred:

Traceback (most recent call last):
  File "/home/airflow/.local/lib/python3.12/site-packages/airflow/task/task_runner/standard_task_runner.py", line 117, in _start_by_fork
    ret = args.func(args, dag=self.dag)
          ^^^^^^^^^^^^^^^^^^^^^^^^^^^^^
  File "/home/airflow/.local/lib/python3.12/site-packages/airflow/cli/cli_config.py", line 49, in command
    return func(*args, **kwargs)
           ^^^^^^^^^^^^^^^^^^^^^
  File "/home/airflow/.local/lib/python3.12/site-packages/airflow/utils/cli.py", line 116, in wrapper
    return f(*args, **kwargs)
           ^^^^^^^^^^^^^^^^^^
  File "/home/airflow/.local/lib/python3.12/site-packages/airflow/cli/commands/task_command.py", line 483, in task_run
    task_return_code = _run_task_by_selected_method(args, _dag, ti)
                       ^^^^^^^^^^^^^^^^^^^^^^^^^^^^^^^^^^^^^^^^^^^^
  File "/home/airflow/.local/lib/python3.12/site-packages/airflow/cli/commands/task_command.py", line 256, in _run_task_by_selected_method
    return _run_raw_task(args, ti)
           ^^^^^^^^^^^^^^^^^^^^^^^
  File "/home/airflow/.local/lib/python3.12/site-packages/airflow/cli/commands/task_command.py", line 341, in _run_raw_task
    return ti._run_raw_task(
           ^^^^^^^^^^^^^^^^^
  File "/home/airflow/.local/lib/python3.12/site-packages/airflow/utils/session.py", line 97, in wrapper
    return func(*args, session=session, **kwargs)
           ^^^^^^^^^^^^^^^^^^^^^^^^^^^^^^^^^^^^^^
  File "/home/airflow/.local/lib/python3.12/site-packages/airflow/models/taskinstance.py", line 3005, in _run_raw_task
    return _run_raw_task(
           ^^^^^^^^^^^^^^
  File "/home/airflow/.local/lib/python3.12/site-packages/airflow/models/taskinstance.py", line 273, in _run_raw_task
    TaskInstance._execute_task_with_callbacks(
  File "/home/airflow/.local/lib/python3.12/site-packages/airflow/models/taskinstance.py", line 3159, in _execute_task_with_callbacks
    result = self._execute_task(context, task_orig)
             ^^^^^^^^^^^^^^^^^^^^^^^^^^^^^^^^^^^^^^
  File "/home/airflow/.local/lib/python3.12/site-packages/airflow/models/taskinstance.py", line 3183, in _execute_task
    return _execute_task(self, context, task_orig)
           ^^^^^^^^^^^^^^^^^^^^^^^^^^^^^^^^^^^^^^^
  File "/home/airflow/.local/lib/python3.12/site-packages/airflow/models/taskinstance.py", line 767, in _execute_task
    result = _execute_callable(context=context, **execute_callable_kwargs)
             ^^^^^^^^^^^^^^^^^^^^^^^^^^^^^^^^^^^^^^^^^^^^^^^^^^^^^^^^^^^^^
  File "/home/airflow/.local/lib/python3.12/site-packages/airflow/models/taskinstance.py", line 733, in _execute_callable
    return ExecutionCallableRunner(
           ^^^^^^^^^^^^^^^^^^^^^^^^
  File "/home/airflow/.local/lib/python3.12/site-packages/airflow/utils/operator_helpers.py", line 252, in run
    return self.func(*args, **kwargs)
           ^^^^^^^^^^^^^^^^^^^^^^^^^^
  File "/home/airflow/.local/lib/python3.12/site-packages/airflow/models/baseoperator.py", line 422, in wrapper
    return func(self, *args, **kwargs)
           ^^^^^^^^^^^^^^^^^^^^^^^^^^^
  File "/home/airflow/.local/lib/python3.12/site-packages/airflow/operators/python.py", line 238, in execute
    return_value = self.execute_callable()
                   ^^^^^^^^^^^^^^^^^^^^^^^
  File "/home/airflow/.local/lib/python3.12/site-packages/airflow/operators/python.py", line 256, in execute_callable
    return runner.run(*self.op_args, **self.op_kwargs)
           ^^^^^^^^^^^^^^^^^^^^^^^^^^^^^^^^^^^^^^^^^^^
  File "/home/airflow/.local/lib/python3.12/site-packages/airflow/utils/operator_helpers.py", line 252, in run
    return self.func(*args, **kwargs)
           ^^^^^^^^^^^^^^^^^^^^^^^^^^
  File "/opt/airflow/dags/api_etl_pipeline.py", line 91, in _validate_aqi_data
    raise ValueError(f"Unexpected error for {city}: {str(e)}")
ValueError: Unexpected error for Pathum_Wan: Invalid data for Pathum_Wan: Missing 'current' key.
[2025-03-30T10:03:23.297+0000] {local_task_job_runner.py:266} INFO - Task exited with return code 1
[2025-03-30T10:03:23.410+0000] {taskinstance.py:3895} INFO - 0 downstream tasks scheduled from follow-on schedule check
[2025-03-30T10:03:23.433+0000] {local_task_job_runner.py:245} INFO - ::endgroup::
