[2025-03-31T02:56:37.600+0000] {local_task_job_runner.py:123} INFO - ::group::Pre task execution logs
[2025-03-31T02:56:37.637+0000] {taskinstance.py:2613} INFO - Dependencies all met for dep_context=non-requeueable deps ti=<TaskInstance: aqi_etl_pipeline.aqi_tasks_group.get_aqi_data_Bangkok scheduled__2025-03-30T00:00:00+00:00 [queued]>
[2025-03-31T02:56:37.649+0000] {taskinstance.py:2613} INFO - Dependencies all met for dep_context=requeueable deps ti=<TaskInstance: aqi_etl_pipeline.aqi_tasks_group.get_aqi_data_Bangkok scheduled__2025-03-30T00:00:00+00:00 [queued]>
[2025-03-31T02:56:37.650+0000] {taskinstance.py:2866} INFO - Starting attempt 3 of 4
[2025-03-31T02:56:37.691+0000] {taskinstance.py:2889} INFO - Executing <Task(PythonOperator): aqi_tasks_group.get_aqi_data_Bangkok> on 2025-03-30 00:00:00+00:00
[2025-03-31T02:56:37.717+0000] {standard_task_runner.py:104} INFO - Running: ['***', 'tasks', 'run', 'aqi_etl_pipeline', 'aqi_tasks_group.get_aqi_data_Bangkok', 'scheduled__2025-03-30T00:00:00+00:00', '--job-id', '754', '--raw', '--subdir', 'DAGS_FOLDER/api_etl_pipeline.py', '--cfg-path', '/tmp/tmp4lt7whq9']
[2025-03-31T02:56:37.721+0000] {standard_task_runner.py:105} INFO - Job 754: Subtask aqi_tasks_group.get_aqi_data_Bangkok
[2025-03-31T02:56:37.744+0000] {logging_mixin.py:190} WARNING - /home/***/.local/lib/python3.12/site-packages/***/task/task_runner/standard_task_runner.py:70 DeprecationWarning: This process (pid=2029) is multi-threaded, use of fork() may lead to deadlocks in the child.
[2025-03-31T02:56:37.748+0000] {standard_task_runner.py:72} INFO - Started process 2055 to run task
[2025-03-31T02:56:37.849+0000] {task_command.py:467} INFO - Running <TaskInstance: aqi_etl_pipeline.aqi_tasks_group.get_aqi_data_Bangkok scheduled__2025-03-30T00:00:00+00:00 [running]> on host 34bd8b30e513
[2025-03-31T02:56:37.976+0000] {taskinstance.py:3132} INFO - Exporting env vars: AIRFLOW_CTX_DAG_OWNER='***' AIRFLOW_CTX_DAG_ID='aqi_etl_pipeline' AIRFLOW_CTX_TASK_ID='aqi_tasks_group.get_aqi_data_Bangkok' AIRFLOW_CTX_EXECUTION_DATE='2025-03-30T00:00:00+00:00' AIRFLOW_CTX_TRY_NUMBER='3' AIRFLOW_CTX_DAG_RUN_ID='scheduled__2025-03-30T00:00:00+00:00'
[2025-03-31T02:56:37.981+0000] {logging_mixin.py:190} INFO - Task instance is in running state
[2025-03-31T02:56:37.981+0000] {logging_mixin.py:190} INFO -  Previous state of the Task instance: queued
[2025-03-31T02:56:37.983+0000] {logging_mixin.py:190} INFO - Current task name:aqi_tasks_group.get_aqi_data_Bangkok state:running start_date:2025-03-31 02:56:37.637688+00:00
[2025-03-31T02:56:37.983+0000] {logging_mixin.py:190} INFO - Dag name:aqi_etl_pipeline and current dag run status:running
[2025-03-31T02:56:37.984+0000] {taskinstance.py:731} INFO - ::endgroup::
[2025-03-31T02:56:38.335+0000] {taskinstance.py:3311} ERROR - Task failed with exception
Traceback (most recent call last):
  File "/home/airflow/.local/lib/python3.12/site-packages/airflow/models/taskinstance.py", line 767, in _execute_task
    result = _execute_callable(context=context, **execute_callable_kwargs)
             ^^^^^^^^^^^^^^^^^^^^^^^^^^^^^^^^^^^^^^^^^^^^^^^^^^^^^^^^^^^^^
  File "/home/airflow/.local/lib/python3.12/site-packages/airflow/models/taskinstance.py", line 733, in _execute_callable
    return ExecutionCallableRunner(
           ^^^^^^^^^^^^^^^^^^^^^^^^
  File "/home/airflow/.local/lib/python3.12/site-packages/airflow/utils/operator_helpers.py", line 252, in run
    return self.func(*args, **kwargs)
           ^^^^^^^^^^^^^^^^^^^^^^^^^^
  File "/home/airflow/.local/lib/python3.12/site-packages/airflow/models/baseoperator.py", line 422, in wrapper
    return func(self, *args, **kwargs)
           ^^^^^^^^^^^^^^^^^^^^^^^^^^^
  File "/home/airflow/.local/lib/python3.12/site-packages/airflow/operators/python.py", line 238, in execute
    return_value = self.execute_callable()
                   ^^^^^^^^^^^^^^^^^^^^^^^
  File "/home/airflow/.local/lib/python3.12/site-packages/airflow/operators/python.py", line 256, in execute_callable
    return runner.run(*self.op_args, **self.op_kwargs)
           ^^^^^^^^^^^^^^^^^^^^^^^^^^^^^^^^^^^^^^^^^^^
  File "/home/airflow/.local/lib/python3.12/site-packages/airflow/utils/operator_helpers.py", line 252, in run
    return self.func(*args, **kwargs)
           ^^^^^^^^^^^^^^^^^^^^^^^^^^
  File "/opt/airflow/dags/api_etl_pipeline.py", line 35, in _get_aqi_data
    raise ValueError(f"API Error {response.status_code}: {response.text}")
ValueError: API Error 400: {"status":"fail","data":{"message":"arguments_missing"}}
[2025-03-31T02:56:38.357+0000] {logging_mixin.py:190} INFO - Task instance in failure state
[2025-03-31T02:56:38.358+0000] {logging_mixin.py:190} INFO - Task start:2025-03-31 02:56:37.637688+00:00 end:2025-03-31 02:56:38.356979+00:00 duration:0.719291
[2025-03-31T02:56:38.359+0000] {logging_mixin.py:190} INFO - Task:<Task(PythonOperator): aqi_tasks_group.get_aqi_data_Bangkok> dag:<DAG: aqi_etl_pipeline> dagrun:<DagRun aqi_etl_pipeline @ 2025-03-30 00:00:00+00:00: scheduled__2025-03-30T00:00:00+00:00, state:running, queued_at: 2025-03-31 01:45:37.384098+00:00. externally triggered: False>
[2025-03-31T02:56:38.360+0000] {logging_mixin.py:190} INFO - Failure caused by API Error 400: {"status":"fail","data":{"message":"arguments_missing"}}
[2025-03-31T02:56:38.361+0000] {taskinstance.py:1225} INFO - Marking task as UP_FOR_RETRY. dag_id=aqi_etl_pipeline, task_id=aqi_tasks_group.get_aqi_data_Bangkok, run_id=scheduled__2025-03-30T00:00:00+00:00, execution_date=20250330T000000, start_date=20250331T025637, end_date=20250331T025638
[2025-03-31T02:56:38.387+0000] {taskinstance.py:340} INFO - ::group::Post task execution logs
[2025-03-31T02:56:38.387+0000] {standard_task_runner.py:124} ERROR - Failed to execute job 754 for task aqi_tasks_group.get_aqi_data_Bangkok (API Error 400: {"status":"fail","data":{"message":"arguments_missing"}}; 2055)
Traceback (most recent call last):
  File "/home/airflow/.local/lib/python3.12/site-packages/airflow/task/task_runner/standard_task_runner.py", line 117, in _start_by_fork
    ret = args.func(args, dag=self.dag)
          ^^^^^^^^^^^^^^^^^^^^^^^^^^^^^
  File "/home/airflow/.local/lib/python3.12/site-packages/airflow/cli/cli_config.py", line 49, in command
    return func(*args, **kwargs)
           ^^^^^^^^^^^^^^^^^^^^^
  File "/home/airflow/.local/lib/python3.12/site-packages/airflow/utils/cli.py", line 116, in wrapper
    return f(*args, **kwargs)
           ^^^^^^^^^^^^^^^^^^
  File "/home/airflow/.local/lib/python3.12/site-packages/airflow/cli/commands/task_command.py", line 483, in task_run
    task_return_code = _run_task_by_selected_method(args, _dag, ti)
                       ^^^^^^^^^^^^^^^^^^^^^^^^^^^^^^^^^^^^^^^^^^^^
  File "/home/airflow/.local/lib/python3.12/site-packages/airflow/cli/commands/task_command.py", line 256, in _run_task_by_selected_method
    return _run_raw_task(args, ti)
           ^^^^^^^^^^^^^^^^^^^^^^^
  File "/home/airflow/.local/lib/python3.12/site-packages/airflow/cli/commands/task_command.py", line 341, in _run_raw_task
    return ti._run_raw_task(
           ^^^^^^^^^^^^^^^^^
  File "/home/airflow/.local/lib/python3.12/site-packages/airflow/utils/session.py", line 97, in wrapper
    return func(*args, session=session, **kwargs)
           ^^^^^^^^^^^^^^^^^^^^^^^^^^^^^^^^^^^^^^
  File "/home/airflow/.local/lib/python3.12/site-packages/airflow/models/taskinstance.py", line 3005, in _run_raw_task
    return _run_raw_task(
           ^^^^^^^^^^^^^^
  File "/home/airflow/.local/lib/python3.12/site-packages/airflow/models/taskinstance.py", line 273, in _run_raw_task
    TaskInstance._execute_task_with_callbacks(
  File "/home/airflow/.local/lib/python3.12/site-packages/airflow/models/taskinstance.py", line 3159, in _execute_task_with_callbacks
    result = self._execute_task(context, task_orig)
             ^^^^^^^^^^^^^^^^^^^^^^^^^^^^^^^^^^^^^^
  File "/home/airflow/.local/lib/python3.12/site-packages/airflow/models/taskinstance.py", line 3183, in _execute_task
    return _execute_task(self, context, task_orig)
           ^^^^^^^^^^^^^^^^^^^^^^^^^^^^^^^^^^^^^^^
  File "/home/airflow/.local/lib/python3.12/site-packages/airflow/models/taskinstance.py", line 767, in _execute_task
    result = _execute_callable(context=context, **execute_callable_kwargs)
             ^^^^^^^^^^^^^^^^^^^^^^^^^^^^^^^^^^^^^^^^^^^^^^^^^^^^^^^^^^^^^
  File "/home/airflow/.local/lib/python3.12/site-packages/airflow/models/taskinstance.py", line 733, in _execute_callable
    return ExecutionCallableRunner(
           ^^^^^^^^^^^^^^^^^^^^^^^^
  File "/home/airflow/.local/lib/python3.12/site-packages/airflow/utils/operator_helpers.py", line 252, in run
    return self.func(*args, **kwargs)
           ^^^^^^^^^^^^^^^^^^^^^^^^^^
  File "/home/airflow/.local/lib/python3.12/site-packages/airflow/models/baseoperator.py", line 422, in wrapper
    return func(self, *args, **kwargs)
           ^^^^^^^^^^^^^^^^^^^^^^^^^^^
  File "/home/airflow/.local/lib/python3.12/site-packages/airflow/operators/python.py", line 238, in execute
    return_value = self.execute_callable()
                   ^^^^^^^^^^^^^^^^^^^^^^^
  File "/home/airflow/.local/lib/python3.12/site-packages/airflow/operators/python.py", line 256, in execute_callable
    return runner.run(*self.op_args, **self.op_kwargs)
           ^^^^^^^^^^^^^^^^^^^^^^^^^^^^^^^^^^^^^^^^^^^
  File "/home/airflow/.local/lib/python3.12/site-packages/airflow/utils/operator_helpers.py", line 252, in run
    return self.func(*args, **kwargs)
           ^^^^^^^^^^^^^^^^^^^^^^^^^^
  File "/opt/airflow/dags/api_etl_pipeline.py", line 35, in _get_aqi_data
    raise ValueError(f"API Error {response.status_code}: {response.text}")
ValueError: API Error 400: {"status":"fail","data":{"message":"arguments_missing"}}
[2025-03-31T02:56:38.417+0000] {local_task_job_runner.py:266} INFO - Task exited with return code 1
[2025-03-31T02:56:38.440+0000] {taskinstance.py:3895} INFO - 0 downstream tasks scheduled from follow-on schedule check
[2025-03-31T02:56:38.442+0000] {local_task_job_runner.py:245} INFO - ::endgroup::
